[2022-09-24T13:49:39.837+0000] {taskinstance.py:1165} INFO - Dependencies all met for <TaskInstance: encasa.prep manual__2022-09-24T13:49:38.592870+00:00 [queued]>
[2022-09-24T13:49:39.845+0000] {taskinstance.py:1165} INFO - Dependencies all met for <TaskInstance: encasa.prep manual__2022-09-24T13:49:38.592870+00:00 [queued]>
[2022-09-24T13:49:39.846+0000] {taskinstance.py:1362} INFO - 
--------------------------------------------------------------------------------
[2022-09-24T13:49:39.846+0000] {taskinstance.py:1363} INFO - Starting attempt 1 of 1
[2022-09-24T13:49:39.847+0000] {taskinstance.py:1364} INFO - 
--------------------------------------------------------------------------------
[2022-09-24T13:49:39.861+0000] {taskinstance.py:1383} INFO - Executing <Task(PythonOperator): prep> on 2022-09-24 13:49:38.592870+00:00
[2022-09-24T13:49:39.866+0000] {standard_task_runner.py:54} INFO - Started process 403 to run task
[2022-09-24T13:49:39.868+0000] {standard_task_runner.py:82} INFO - Running: ['***', 'tasks', 'run', 'encasa', 'prep', 'manual__2022-09-24T13:49:38.592870+00:00', '--job-id', '24', '--raw', '--subdir', 'DAGS_FOLDER/dag.py', '--cfg-path', '/tmp/tmpq9br2kbc']
[2022-09-24T13:49:39.868+0000] {standard_task_runner.py:83} INFO - Job 24: Subtask prep
[2022-09-24T13:49:39.869+0000] {dagbag.py:525} INFO - Filling up the DagBag from /opt/***/dags/dag.py
[2022-09-24T13:49:40.306+0000] {task_command.py:384} INFO - Running <TaskInstance: encasa.prep manual__2022-09-24T13:49:38.592870+00:00 [running]> on host bcf5bbb5575a
[2022-09-24T13:49:40.373+0000] {taskinstance.py:1592} INFO - Exporting the following env vars:
AIRFLOW_CTX_DAG_OWNER=***
AIRFLOW_CTX_DAG_ID=encasa
AIRFLOW_CTX_TASK_ID=prep
AIRFLOW_CTX_EXECUTION_DATE=2022-09-24T13:49:38.592870+00:00
AIRFLOW_CTX_TRY_NUMBER=1
AIRFLOW_CTX_DAG_RUN_ID=manual__2022-09-24T13:49:38.592870+00:00
[2022-09-24T13:49:40.374+0000] {tasks.py:110} INFO - Reading the last request file for day 24/09/2022
[2022-09-24T13:49:40.375+0000] {taskinstance.py:1851} ERROR - Task failed with exception
Traceback (most recent call last):
  File "/home/airflow/.local/lib/python3.7/site-packages/airflow/operators/python.py", line 175, in execute
    return_value = self.execute_callable()
  File "/home/airflow/.local/lib/python3.7/site-packages/airflow/operators/python.py", line 193, in execute_callable
    return self.python_callable(*self.op_args, **self.op_kwargs)
  File "/opt/airflow/dags/tasks.py", line 114, in prep
    for files in os.listdir(INPUT_DIR):
FileNotFoundError: [Errno 2] No such file or directory: 'W:/Coleta Web/PROJETO PILOTO/BASE_PROJETO/Encomenda'
[2022-09-24T13:49:40.385+0000] {taskinstance.py:1406} INFO - Marking task as FAILED. dag_id=encasa, task_id=prep, execution_date=20220924T134938, start_date=20220924T134939, end_date=20220924T134940
[2022-09-24T13:49:40.395+0000] {standard_task_runner.py:107} ERROR - Failed to execute job 24 for task prep ([Errno 2] No such file or directory: 'W:/Coleta Web/PROJETO PILOTO/BASE_PROJETO/Encomenda'; 403)
[2022-09-24T13:49:40.405+0000] {local_task_job.py:164} INFO - Task exited with return code 1
[2022-09-24T13:49:40.430+0000] {local_task_job.py:273} INFO - 0 downstream tasks scheduled from follow-on schedule check
