[2022-10-09T23:09:56.526+0000] {taskinstance.py:1165} INFO - Dependencies all met for <TaskInstance: cemaco.prep scheduled__2022-08-11T00:00:00+00:00 [queued]>
[2022-10-09T23:09:56.537+0000] {taskinstance.py:1165} INFO - Dependencies all met for <TaskInstance: cemaco.prep scheduled__2022-08-11T00:00:00+00:00 [queued]>
[2022-10-09T23:09:56.538+0000] {taskinstance.py:1362} INFO - 
--------------------------------------------------------------------------------
[2022-10-09T23:09:56.538+0000] {taskinstance.py:1363} INFO - Starting attempt 1 of 1
[2022-10-09T23:09:56.538+0000] {taskinstance.py:1364} INFO - 
--------------------------------------------------------------------------------
[2022-10-09T23:09:56.553+0000] {taskinstance.py:1383} INFO - Executing <Task(PythonOperator): prep> on 2022-08-11 00:00:00+00:00
[2022-10-09T23:09:56.557+0000] {standard_task_runner.py:54} INFO - Started process 105 to run task
[2022-10-09T23:09:56.559+0000] {standard_task_runner.py:82} INFO - Running: ['***', 'tasks', 'run', 'cemaco', 'prep', 'scheduled__2022-08-11T00:00:00+00:00', '--job-id', '7', '--raw', '--subdir', 'DAGS_FOLDER/dag.py', '--cfg-path', '/tmp/tmp5lac19hc']
[2022-10-09T23:09:56.560+0000] {standard_task_runner.py:83} INFO - Job 7: Subtask prep
[2022-10-09T23:09:56.561+0000] {dagbag.py:525} INFO - Filling up the DagBag from /opt/***/dags/dag.py
[2022-10-09T23:09:57.398+0000] {task_command.py:384} INFO - Running <TaskInstance: cemaco.prep scheduled__2022-08-11T00:00:00+00:00 [running]> on host 7dcbfa2899a4
[2022-10-09T23:09:57.463+0000] {taskinstance.py:1592} INFO - Exporting the following env vars:
AIRFLOW_CTX_DAG_OWNER=***
AIRFLOW_CTX_DAG_ID=cemaco
AIRFLOW_CTX_TASK_ID=prep
AIRFLOW_CTX_EXECUTION_DATE=2022-08-11T00:00:00+00:00
AIRFLOW_CTX_TRY_NUMBER=1
AIRFLOW_CTX_DAG_RUN_ID=scheduled__2022-08-11T00:00:00+00:00
[2022-10-09T23:09:57.464+0000] {tasks.py:83} INFO - Reading the last request file for day 09/10/2022
[2022-10-09T23:09:57.473+0000] {tasks.py:62} INFO - Cleaning the column name
[2022-10-09T23:09:57.476+0000] {taskinstance.py:1851} ERROR - Task failed with exception
Traceback (most recent call last):
  File "/home/airflow/.local/lib/python3.7/site-packages/pandas/core/indexes/base.py", line 3361, in get_loc
    return self._engine.get_loc(casted_key)
  File "pandas/_libs/index.pyx", line 76, in pandas._libs.index.IndexEngine.get_loc
  File "pandas/_libs/index.pyx", line 108, in pandas._libs.index.IndexEngine.get_loc
  File "pandas/_libs/hashtable_class_helper.pxi", line 5198, in pandas._libs.hashtable.PyObjectHashTable.get_item
  File "pandas/_libs/hashtable_class_helper.pxi", line 5206, in pandas._libs.hashtable.PyObjectHashTable.get_item
KeyError: 'name'

The above exception was the direct cause of the following exception:

Traceback (most recent call last):
  File "/home/airflow/.local/lib/python3.7/site-packages/airflow/operators/python.py", line 175, in execute
    return_value = self.execute_callable()
  File "/home/airflow/.local/lib/python3.7/site-packages/airflow/operators/python.py", line 193, in execute_callable
    return self.python_callable(*self.op_args, **self.op_kwargs)
  File "/opt/airflow/dags/tasks.py", line 96, in prep
    dataframe = cleaner(dataframe)
  File "/opt/airflow/dags/tasks.py", line 63, in cleaner
    dataframe["cleaner_name"] = dataframe["name"].copy()
  File "/home/airflow/.local/lib/python3.7/site-packages/pandas/core/frame.py", line 3458, in __getitem__
    indexer = self.columns.get_loc(key)
  File "/home/airflow/.local/lib/python3.7/site-packages/pandas/core/indexes/base.py", line 3363, in get_loc
    raise KeyError(key) from err
KeyError: 'name'
[2022-10-09T23:09:57.489+0000] {taskinstance.py:1406} INFO - Marking task as FAILED. dag_id=cemaco, task_id=prep, execution_date=20220811T000000, start_date=20221009T230956, end_date=20221009T230957
[2022-10-09T23:09:57.499+0000] {standard_task_runner.py:107} ERROR - Failed to execute job 7 for task prep ('name'; 105)
[2022-10-09T23:09:57.534+0000] {local_task_job.py:164} INFO - Task exited with return code 1
[2022-10-09T23:09:57.559+0000] {local_task_job.py:273} INFO - 0 downstream tasks scheduled from follow-on schedule check
