[2022-09-27T20:48:17.934+0000] {taskinstance.py:1165} INFO - Dependencies all met for <TaskInstance: casa_das_ferragens.prep manual__2022-09-27T19:59:55.516392+00:00 [queued]>
[2022-09-27T20:48:17.943+0000] {taskinstance.py:1165} INFO - Dependencies all met for <TaskInstance: casa_das_ferragens.prep manual__2022-09-27T19:59:55.516392+00:00 [queued]>
[2022-09-27T20:48:17.943+0000] {taskinstance.py:1362} INFO - 
--------------------------------------------------------------------------------
[2022-09-27T20:48:17.944+0000] {taskinstance.py:1363} INFO - Starting attempt 3 of 3
[2022-09-27T20:48:17.944+0000] {taskinstance.py:1364} INFO - 
--------------------------------------------------------------------------------
[2022-09-27T20:48:17.957+0000] {taskinstance.py:1383} INFO - Executing <Task(PythonOperator): prep> on 2022-09-27 19:59:55.516392+00:00
[2022-09-27T20:48:17.962+0000] {standard_task_runner.py:54} INFO - Started process 186 to run task
[2022-09-27T20:48:17.964+0000] {standard_task_runner.py:82} INFO - Running: ['***', 'tasks', 'run', 'casa_das_ferragens', 'prep', 'manual__2022-09-27T19:59:55.516392+00:00', '--job-id', '299', '--raw', '--subdir', 'DAGS_FOLDER/dag.py', '--cfg-path', '/tmp/tmpi9megxjb']
[2022-09-27T20:48:17.964+0000] {standard_task_runner.py:83} INFO - Job 299: Subtask prep
[2022-09-27T20:48:17.965+0000] {dagbag.py:525} INFO - Filling up the DagBag from /opt/***/dags/dag.py
[2022-09-27T20:48:18.988+0000] {task_command.py:384} INFO - Running <TaskInstance: casa_das_ferragens.prep manual__2022-09-27T19:59:55.516392+00:00 [running]> on host 4f0e9a210a6d
[2022-09-27T20:48:19.062+0000] {taskinstance.py:1592} INFO - Exporting the following env vars:
AIRFLOW_CTX_DAG_OWNER=***
AIRFLOW_CTX_DAG_ID=casa_das_ferragens
AIRFLOW_CTX_TASK_ID=prep
AIRFLOW_CTX_EXECUTION_DATE=2022-09-27T19:59:55.516392+00:00
AIRFLOW_CTX_TRY_NUMBER=3
AIRFLOW_CTX_DAG_RUN_ID=manual__2022-09-27T19:59:55.516392+00:00
[2022-09-27T20:48:19.063+0000] {tasks.py:112} INFO - Reading the last request file for day 27/09/2022
[2022-09-27T20:48:19.064+0000] {taskinstance.py:1851} ERROR - Task failed with exception
Traceback (most recent call last):
  File "/home/airflow/.local/lib/python3.7/site-packages/airflow/operators/python.py", line 175, in execute
    return_value = self.execute_callable()
  File "/home/airflow/.local/lib/python3.7/site-packages/airflow/operators/python.py", line 193, in execute_callable
    return self.python_callable(*self.op_args, **self.op_kwargs)
  File "/opt/airflow/dags/tasks.py", line 117, in prep
    for files in os.listdir(INPUT_DIR):
FileNotFoundError: [Errno 2] No such file or directory: './Encomenda'
[2022-09-27T20:48:19.074+0000] {taskinstance.py:1406} INFO - Marking task as FAILED. dag_id=casa_das_ferragens, task_id=prep, execution_date=20220927T195955, start_date=20220927T204817, end_date=20220927T204819
[2022-09-27T20:48:19.085+0000] {standard_task_runner.py:107} ERROR - Failed to execute job 299 for task prep ([Errno 2] No such file or directory: './Encomenda'; 186)
[2022-09-27T20:48:19.099+0000] {local_task_job.py:164} INFO - Task exited with return code 1
[2022-09-27T20:48:19.128+0000] {local_task_job.py:273} INFO - 0 downstream tasks scheduled from follow-on schedule check
