[2022-09-23T15:05:44.410+0000] {taskinstance.py:1165} INFO - Dependencies all met for <TaskInstance: encasa._prep_ manual__2022-09-23T15:05:43.640762+00:00 [queued]>
[2022-09-23T15:05:44.420+0000] {taskinstance.py:1165} INFO - Dependencies all met for <TaskInstance: encasa._prep_ manual__2022-09-23T15:05:43.640762+00:00 [queued]>
[2022-09-23T15:05:44.421+0000] {taskinstance.py:1362} INFO - 
--------------------------------------------------------------------------------
[2022-09-23T15:05:44.421+0000] {taskinstance.py:1363} INFO - Starting attempt 1 of 1
[2022-09-23T15:05:44.421+0000] {taskinstance.py:1364} INFO - 
--------------------------------------------------------------------------------
[2022-09-23T15:05:44.435+0000] {taskinstance.py:1383} INFO - Executing <Task(PythonOperator): _prep_> on 2022-09-23 15:05:43.640762+00:00
[2022-09-23T15:05:44.439+0000] {standard_task_runner.py:54} INFO - Started process 108 to run task
[2022-09-23T15:05:44.443+0000] {standard_task_runner.py:82} INFO - Running: ['***', 'tasks', 'run', 'encasa', '_prep_', 'manual__2022-09-23T15:05:43.640762+00:00', '--job-id', '18', '--raw', '--subdir', 'DAGS_FOLDER/dag.py', '--cfg-path', '/tmp/tmpmv4zfhjs']
[2022-09-23T15:05:44.443+0000] {standard_task_runner.py:83} INFO - Job 18: Subtask _prep_
[2022-09-23T15:05:44.444+0000] {dagbag.py:525} INFO - Filling up the DagBag from /opt/***/dags/dag.py
[2022-09-23T15:05:44.864+0000] {task_command.py:384} INFO - Running <TaskInstance: encasa._prep_ manual__2022-09-23T15:05:43.640762+00:00 [running]> on host bcf5bbb5575a
[2022-09-23T15:05:44.925+0000] {taskinstance.py:1592} INFO - Exporting the following env vars:
AIRFLOW_CTX_DAG_OWNER=***
AIRFLOW_CTX_DAG_ID=encasa
AIRFLOW_CTX_TASK_ID=_prep_
AIRFLOW_CTX_EXECUTION_DATE=2022-09-23T15:05:43.640762+00:00
AIRFLOW_CTX_TRY_NUMBER=1
AIRFLOW_CTX_DAG_RUN_ID=manual__2022-09-23T15:05:43.640762+00:00
[2022-09-23T15:05:44.926+0000] {taskinstance.py:1851} ERROR - Task failed with exception
Traceback (most recent call last):
  File "/home/airflow/.local/lib/python3.7/site-packages/airflow/operators/python.py", line 175, in execute
    return_value = self.execute_callable()
  File "/home/airflow/.local/lib/python3.7/site-packages/airflow/operators/python.py", line 193, in execute_callable
    return self.python_callable(*self.op_args, **self.op_kwargs)
  File "/opt/airflow/dags/tasks.py", line 98, in _prep_
    f"Reading the last request file for day {_get_path_date(config)[0].strftime('%d/%m/%Y')}"
  File "/opt/airflow/dags/tasks.py", line 57, in _get_path_date
    f'{config["out_dir"]}/coleta_%Y/coleta_%B/coleta{_request_dec(int(date.strftime("%d")))}/saida_%Y_%m_%d'
KeyError: 'out_dir'
[2022-09-23T15:05:44.935+0000] {taskinstance.py:1406} INFO - Marking task as FAILED. dag_id=encasa, task_id=_prep_, execution_date=20220923T150543, start_date=20220923T150544, end_date=20220923T150544
[2022-09-23T15:05:44.945+0000] {standard_task_runner.py:107} ERROR - Failed to execute job 18 for task _prep_ ('out_dir'; 108)
[2022-09-23T15:05:44.976+0000] {local_task_job.py:164} INFO - Task exited with return code 1
[2022-09-23T15:05:45.001+0000] {local_task_job.py:273} INFO - 0 downstream tasks scheduled from follow-on schedule check
