[2022-09-24T13:42:34.650+0000] {taskinstance.py:1165} INFO - Dependencies all met for <TaskInstance: encasa.prep scheduled__2022-09-23T00:00:00+00:00 [queued]>
[2022-09-24T13:42:34.660+0000] {taskinstance.py:1165} INFO - Dependencies all met for <TaskInstance: encasa.prep scheduled__2022-09-23T00:00:00+00:00 [queued]>
[2022-09-24T13:42:34.661+0000] {taskinstance.py:1362} INFO - 
--------------------------------------------------------------------------------
[2022-09-24T13:42:34.661+0000] {taskinstance.py:1363} INFO - Starting attempt 1 of 1
[2022-09-24T13:42:34.662+0000] {taskinstance.py:1364} INFO - 
--------------------------------------------------------------------------------
[2022-09-24T13:42:34.676+0000] {taskinstance.py:1383} INFO - Executing <Task(PythonOperator): prep> on 2022-09-23 00:00:00+00:00
[2022-09-24T13:42:34.683+0000] {standard_task_runner.py:54} INFO - Started process 69 to run task
[2022-09-24T13:42:34.686+0000] {standard_task_runner.py:82} INFO - Running: ['***', 'tasks', 'run', 'encasa', 'prep', 'scheduled__2022-09-23T00:00:00+00:00', '--job-id', '21', '--raw', '--subdir', 'DAGS_FOLDER/dag.py', '--cfg-path', '/tmp/tmpzme9u51l']
[2022-09-24T13:42:34.687+0000] {standard_task_runner.py:83} INFO - Job 21: Subtask prep
[2022-09-24T13:42:34.687+0000] {dagbag.py:525} INFO - Filling up the DagBag from /opt/***/dags/dag.py
[2022-09-24T13:42:36.141+0000] {task_command.py:384} INFO - Running <TaskInstance: encasa.prep scheduled__2022-09-23T00:00:00+00:00 [running]> on host bcf5bbb5575a
[2022-09-24T13:42:36.224+0000] {taskinstance.py:1592} INFO - Exporting the following env vars:
AIRFLOW_CTX_DAG_OWNER=***
AIRFLOW_CTX_DAG_ID=encasa
AIRFLOW_CTX_TASK_ID=prep
AIRFLOW_CTX_EXECUTION_DATE=2022-09-23T00:00:00+00:00
AIRFLOW_CTX_TRY_NUMBER=1
AIRFLOW_CTX_DAG_RUN_ID=scheduled__2022-09-23T00:00:00+00:00
[2022-09-24T13:42:36.225+0000] {taskinstance.py:1851} ERROR - Task failed with exception
Traceback (most recent call last):
  File "/home/airflow/.local/lib/python3.7/site-packages/airflow/operators/python.py", line 175, in execute
    return_value = self.execute_callable()
  File "/home/airflow/.local/lib/python3.7/site-packages/airflow/operators/python.py", line 193, in execute_callable
    return self.python_callable(*self.op_args, **self.op_kwargs)
TypeError: prep() missing 1 required positional argument: 'date'
[2022-09-24T13:42:36.233+0000] {taskinstance.py:1406} INFO - Marking task as FAILED. dag_id=encasa, task_id=prep, execution_date=20220923T000000, start_date=20220924T134234, end_date=20220924T134236
[2022-09-24T13:42:36.249+0000] {standard_task_runner.py:107} ERROR - Failed to execute job 21 for task prep (prep() missing 1 required positional argument: 'date'; 69)
[2022-09-24T13:42:36.263+0000] {local_task_job.py:164} INFO - Task exited with return code 1
[2022-09-24T13:42:36.294+0000] {local_task_job.py:273} INFO - 0 downstream tasks scheduled from follow-on schedule check
