[2022-09-26T16:42:18.013+0000] {taskinstance.py:1165} INFO - Dependencies all met for <TaskInstance: tudo_melhor.colector scheduled__2022-08-21T00:00:00+00:00 [queued]>
[2022-09-26T16:42:18.022+0000] {taskinstance.py:1165} INFO - Dependencies all met for <TaskInstance: tudo_melhor.colector scheduled__2022-08-21T00:00:00+00:00 [queued]>
[2022-09-26T16:42:18.022+0000] {taskinstance.py:1362} INFO - 
--------------------------------------------------------------------------------
[2022-09-26T16:42:18.023+0000] {taskinstance.py:1363} INFO - Starting attempt 24 of 24
[2022-09-26T16:42:18.023+0000] {taskinstance.py:1364} INFO - 
--------------------------------------------------------------------------------
[2022-09-26T16:42:18.037+0000] {taskinstance.py:1383} INFO - Executing <Task(PythonOperator): colector> on 2022-08-21 00:00:00+00:00
[2022-09-26T16:42:18.041+0000] {standard_task_runner.py:54} INFO - Started process 150 to run task
[2022-09-26T16:42:18.043+0000] {standard_task_runner.py:82} INFO - Running: ['***', 'tasks', 'run', 'tudo_melhor', 'colector', 'scheduled__2022-08-21T00:00:00+00:00', '--job-id', '246', '--raw', '--subdir', 'DAGS_FOLDER/dag.py', '--cfg-path', '/tmp/tmprm63u6ap']
[2022-09-26T16:42:18.043+0000] {standard_task_runner.py:83} INFO - Job 246: Subtask colector
[2022-09-26T16:42:18.044+0000] {dagbag.py:525} INFO - Filling up the DagBag from /opt/***/dags/dag.py
[2022-09-26T16:42:18.939+0000] {task_command.py:384} INFO - Running <TaskInstance: tudo_melhor.colector scheduled__2022-08-21T00:00:00+00:00 [running]> on host 39fe3eff96a1
[2022-09-26T16:42:18.999+0000] {taskinstance.py:1592} INFO - Exporting the following env vars:
AIRFLOW_CTX_DAG_OWNER=***
AIRFLOW_CTX_DAG_ID=tudo_melhor
AIRFLOW_CTX_TASK_ID=colector
AIRFLOW_CTX_EXECUTION_DATE=2022-08-21T00:00:00+00:00
AIRFLOW_CTX_TRY_NUMBER=24
AIRFLOW_CTX_DAG_RUN_ID=scheduled__2022-08-21T00:00:00+00:00
[2022-09-26T16:42:19.000+0000] {tasks.py:42} INFO - Defining DEC to export information
[2022-09-26T16:42:19.007+0000] {tasks.py:358} INFO - Reading prep dataframe
[2022-09-26T16:42:19.022+0000] {tasks.py:150} INFO - Instantiating the Browser with the requested settings
[2022-09-26T16:42:19.025+0000] {connectionpool.py:813} WARNING - Retrying (Retry(total=2, connect=None, read=None, redirect=None, status=None)) after connection broken by 'NewConnectionError('<urllib3.connection.HTTPConnection object at 0x7fbcf347b290>: Failed to establish a new connection: [Errno 111] Connection refused')': /session
[2022-09-26T16:42:19.025+0000] {connectionpool.py:813} WARNING - Retrying (Retry(total=1, connect=None, read=None, redirect=None, status=None)) after connection broken by 'NewConnectionError('<urllib3.connection.HTTPConnection object at 0x7fbcf3452b50>: Failed to establish a new connection: [Errno 111] Connection refused')': /session
[2022-09-26T16:42:19.026+0000] {connectionpool.py:813} WARNING - Retrying (Retry(total=0, connect=None, read=None, redirect=None, status=None)) after connection broken by 'NewConnectionError('<urllib3.connection.HTTPConnection object at 0x7fbcf3476690>: Failed to establish a new connection: [Errno 111] Connection refused')': /session
[2022-09-26T16:42:19.027+0000] {taskinstance.py:1851} ERROR - Task failed with exception
Traceback (most recent call last):
  File "/home/airflow/.local/lib/python3.7/site-packages/urllib3/connection.py", line 175, in _new_conn
    (self._dns_host, self.port), self.timeout, **extra_kw
  File "/home/airflow/.local/lib/python3.7/site-packages/urllib3/util/connection.py", line 95, in create_connection
    raise err
  File "/home/airflow/.local/lib/python3.7/site-packages/urllib3/util/connection.py", line 85, in create_connection
    sock.connect(sa)
ConnectionRefusedError: [Errno 111] Connection refused

During handling of the above exception, another exception occurred:

Traceback (most recent call last):
  File "/home/airflow/.local/lib/python3.7/site-packages/urllib3/connectionpool.py", line 710, in urlopen
    chunked=chunked,
  File "/home/airflow/.local/lib/python3.7/site-packages/urllib3/connectionpool.py", line 398, in _make_request
    conn.request(method, url, **httplib_request_kw)
  File "/home/airflow/.local/lib/python3.7/site-packages/urllib3/connection.py", line 239, in request
    super(HTTPConnection, self).request(method, url, body=body, headers=headers)
  File "/usr/local/lib/python3.7/http/client.py", line 1281, in request
    self._send_request(method, url, body, headers, encode_chunked)
  File "/usr/local/lib/python3.7/http/client.py", line 1327, in _send_request
    self.endheaders(body, encode_chunked=encode_chunked)
  File "/usr/local/lib/python3.7/http/client.py", line 1276, in endheaders
    self._send_output(message_body, encode_chunked=encode_chunked)
  File "/usr/local/lib/python3.7/http/client.py", line 1036, in _send_output
    self.send(msg)
  File "/usr/local/lib/python3.7/http/client.py", line 976, in send
    self.connect()
  File "/home/airflow/.local/lib/python3.7/site-packages/urllib3/connection.py", line 205, in connect
    conn = self._new_conn()
  File "/home/airflow/.local/lib/python3.7/site-packages/urllib3/connection.py", line 187, in _new_conn
    self, "Failed to establish a new connection: %s" % e
urllib3.exceptions.NewConnectionError: <urllib3.connection.HTTPConnection object at 0x7fbcf3476910>: Failed to establish a new connection: [Errno 111] Connection refused

During handling of the above exception, another exception occurred:

Traceback (most recent call last):
  File "/home/airflow/.local/lib/python3.7/site-packages/airflow/operators/python.py", line 175, in execute
    return_value = self.execute_callable()
  File "/home/airflow/.local/lib/python3.7/site-packages/airflow/operators/python.py", line 193, in execute_callable
    return self.python_callable(*self.op_args, **self.op_kwargs)
  File "/opt/airflow/dags/tasks.py", line 360, in colector
    browser = config_browser(config)
  File "/opt/airflow/dags/tasks.py", line 164, in config_browser
    desired_capabilities=capabilities)
  File "/home/airflow/.local/lib/python3.7/site-packages/selenium/webdriver/remote/webdriver.py", line 270, in __init__
    self.start_session(capabilities, browser_profile)
  File "/home/airflow/.local/lib/python3.7/site-packages/selenium/webdriver/remote/webdriver.py", line 363, in start_session
    response = self.execute(Command.NEW_SESSION, parameters)
  File "/home/airflow/.local/lib/python3.7/site-packages/selenium/webdriver/remote/webdriver.py", line 426, in execute
    response = self.command_executor.execute(driver_command, params)
  File "/home/airflow/.local/lib/python3.7/site-packages/selenium/webdriver/remote/remote_connection.py", line 344, in execute
    return self._request(command_info[0], url, body=data)
  File "/home/airflow/.local/lib/python3.7/site-packages/selenium/webdriver/remote/remote_connection.py", line 366, in _request
    response = self._conn.request(method, url, body=body, headers=headers)
  File "/home/airflow/.local/lib/python3.7/site-packages/urllib3/request.py", line 79, in request
    method, url, fields=fields, headers=headers, **urlopen_kw
  File "/home/airflow/.local/lib/python3.7/site-packages/urllib3/request.py", line 170, in request_encode_body
    return self.urlopen(method, url, **extra_kw)
  File "/home/airflow/.local/lib/python3.7/site-packages/urllib3/poolmanager.py", line 376, in urlopen
    response = conn.urlopen(method, u.request_uri, **kw)
  File "/home/airflow/.local/lib/python3.7/site-packages/urllib3/connectionpool.py", line 828, in urlopen
    **response_kw
  File "/home/airflow/.local/lib/python3.7/site-packages/urllib3/connectionpool.py", line 828, in urlopen
    **response_kw
  File "/home/airflow/.local/lib/python3.7/site-packages/urllib3/connectionpool.py", line 828, in urlopen
    **response_kw
  File "/home/airflow/.local/lib/python3.7/site-packages/urllib3/connectionpool.py", line 788, in urlopen
    method, url, error=e, _pool=self, _stacktrace=sys.exc_info()[2]
  File "/home/airflow/.local/lib/python3.7/site-packages/urllib3/util/retry.py", line 592, in increment
    raise MaxRetryError(_pool, url, error or ResponseError(cause))
urllib3.exceptions.MaxRetryError: HTTPConnectionPool(host='localhost', port=4444): Max retries exceeded with url: /session (Caused by NewConnectionError('<urllib3.connection.HTTPConnection object at 0x7fbcf3476910>: Failed to establish a new connection: [Errno 111] Connection refused'))
[2022-09-26T16:42:19.038+0000] {taskinstance.py:1406} INFO - Marking task as FAILED. dag_id=tudo_melhor, task_id=colector, execution_date=20220821T000000, start_date=20220926T164218, end_date=20220926T164219
[2022-09-26T16:42:19.049+0000] {standard_task_runner.py:107} ERROR - Failed to execute job 246 for task colector (HTTPConnectionPool(host='localhost', port=4444): Max retries exceeded with url: /session (Caused by NewConnectionError('<urllib3.connection.HTTPConnection object at 0x7fbcf3476910>: Failed to establish a new connection: [Errno 111] Connection refused')); 150)
[2022-09-26T16:42:19.058+0000] {local_task_job.py:164} INFO - Task exited with return code 1
[2022-09-26T16:42:19.082+0000] {local_task_job.py:273} INFO - 0 downstream tasks scheduled from follow-on schedule check
