[2022-09-26T04:08:26.381+0000] {taskinstance.py:1165} INFO - Dependencies all met for <TaskInstance: tudo_melhor.colector scheduled__2022-08-21T00:00:00+00:00 [queued]>
[2022-09-26T04:08:26.391+0000] {taskinstance.py:1165} INFO - Dependencies all met for <TaskInstance: tudo_melhor.colector scheduled__2022-08-21T00:00:00+00:00 [queued]>
[2022-09-26T04:08:26.392+0000] {taskinstance.py:1362} INFO - 
--------------------------------------------------------------------------------
[2022-09-26T04:08:26.392+0000] {taskinstance.py:1363} INFO - Starting attempt 9 of 9
[2022-09-26T04:08:26.393+0000] {taskinstance.py:1364} INFO - 
--------------------------------------------------------------------------------
[2022-09-26T04:08:26.406+0000] {taskinstance.py:1383} INFO - Executing <Task(PythonOperator): colector> on 2022-08-21 00:00:00+00:00
[2022-09-26T04:08:26.412+0000] {standard_task_runner.py:54} INFO - Started process 733 to run task
[2022-09-26T04:08:26.414+0000] {standard_task_runner.py:82} INFO - Running: ['***', 'tasks', 'run', 'tudo_melhor', 'colector', 'scheduled__2022-08-21T00:00:00+00:00', '--job-id', '74', '--raw', '--subdir', 'DAGS_FOLDER/dag.py', '--cfg-path', '/tmp/tmp79mufz07']
[2022-09-26T04:08:26.414+0000] {standard_task_runner.py:83} INFO - Job 74: Subtask colector
[2022-09-26T04:08:26.415+0000] {dagbag.py:525} INFO - Filling up the DagBag from /opt/***/dags/dag.py
[2022-09-26T04:08:26.855+0000] {task_command.py:384} INFO - Running <TaskInstance: tudo_melhor.colector scheduled__2022-08-21T00:00:00+00:00 [running]> on host f43703b1b479
[2022-09-26T04:08:26.918+0000] {taskinstance.py:1592} INFO - Exporting the following env vars:
AIRFLOW_CTX_DAG_OWNER=***
AIRFLOW_CTX_DAG_ID=tudo_melhor
AIRFLOW_CTX_TASK_ID=colector
AIRFLOW_CTX_EXECUTION_DATE=2022-08-21T00:00:00+00:00
AIRFLOW_CTX_TRY_NUMBER=9
AIRFLOW_CTX_DAG_RUN_ID=scheduled__2022-08-21T00:00:00+00:00
[2022-09-26T04:08:26.919+0000] {tasks.py:41} INFO - Defining DEC to export information
[2022-09-26T04:08:26.925+0000] {tasks.py:359} INFO - Reading prep dataframe
[2022-09-26T04:08:26.936+0000] {tasks.py:149} INFO - Instantiating the Browser with the requested settings
[2022-09-26T04:08:26.937+0000] {taskinstance.py:1851} ERROR - Task failed with exception
Traceback (most recent call last):
  File "/home/airflow/.local/lib/python3.7/site-packages/airflow/operators/python.py", line 175, in execute
    return_value = self.execute_callable()
  File "/home/airflow/.local/lib/python3.7/site-packages/airflow/operators/python.py", line 193, in execute_callable
    return self.python_callable(*self.op_args, **self.op_kwargs)
  File "/opt/airflow/dags/tasks.py", line 361, in colector
    browser = config_browser(config)
  File "/opt/airflow/dags/tasks.py", line 165, in config_browser
    options=options)
  File "/home/airflow/.local/lib/python3.7/site-packages/selenium/webdriver/remote/webdriver.py", line 270, in __init__
    self.start_session(capabilities, browser_profile)
  File "/home/airflow/.local/lib/python3.7/site-packages/selenium/webdriver/remote/webdriver.py", line 363, in start_session
    response = self.execute(Command.NEW_SESSION, parameters)
  File "/home/airflow/.local/lib/python3.7/site-packages/selenium/webdriver/remote/webdriver.py", line 426, in execute
    response = self.command_executor.execute(driver_command, params)
  File "/home/airflow/.local/lib/python3.7/site-packages/selenium/webdriver/remote/remote_connection.py", line 344, in execute
    return self._request(command_info[0], url, body=data)
  File "/home/airflow/.local/lib/python3.7/site-packages/selenium/webdriver/remote/remote_connection.py", line 366, in _request
    response = self._conn.request(method, url, body=body, headers=headers)
  File "/home/airflow/.local/lib/python3.7/site-packages/urllib3/request.py", line 79, in request
    method, url, fields=fields, headers=headers, **urlopen_kw
  File "/home/airflow/.local/lib/python3.7/site-packages/urllib3/request.py", line 170, in request_encode_body
    return self.urlopen(method, url, **extra_kw)
  File "/home/airflow/.local/lib/python3.7/site-packages/urllib3/poolmanager.py", line 365, in urlopen
    conn = self.connection_from_host(u.host, port=u.port, scheme=u.scheme)
  File "/home/airflow/.local/lib/python3.7/site-packages/urllib3/poolmanager.py", line 237, in connection_from_host
    raise LocationValueError("No host specified.")
urllib3.exceptions.LocationValueError: No host specified.
[2022-09-26T04:08:26.947+0000] {taskinstance.py:1406} INFO - Marking task as FAILED. dag_id=tudo_melhor, task_id=colector, execution_date=20220821T000000, start_date=20220926T040826, end_date=20220926T040826
[2022-09-26T04:08:26.957+0000] {standard_task_runner.py:107} ERROR - Failed to execute job 74 for task colector (No host specified.; 733)
[2022-09-26T04:08:26.988+0000] {local_task_job.py:164} INFO - Task exited with return code 1
[2022-09-26T04:08:27.013+0000] {local_task_job.py:273} INFO - 0 downstream tasks scheduled from follow-on schedule check
