[2022-09-26T03:43:21.429+0000] {taskinstance.py:1165} INFO - Dependencies all met for <TaskInstance: tudo_melhor.colector scheduled__2022-08-21T00:00:00+00:00 [queued]>
[2022-09-26T03:43:21.437+0000] {taskinstance.py:1165} INFO - Dependencies all met for <TaskInstance: tudo_melhor.colector scheduled__2022-08-21T00:00:00+00:00 [queued]>
[2022-09-26T03:43:21.437+0000] {taskinstance.py:1362} INFO - 
--------------------------------------------------------------------------------
[2022-09-26T03:43:21.438+0000] {taskinstance.py:1363} INFO - Starting attempt 2 of 2
[2022-09-26T03:43:21.438+0000] {taskinstance.py:1364} INFO - 
--------------------------------------------------------------------------------
[2022-09-26T03:43:21.451+0000] {taskinstance.py:1383} INFO - Executing <Task(PythonOperator): colector> on 2022-08-21 00:00:00+00:00
[2022-09-26T03:43:21.455+0000] {standard_task_runner.py:54} INFO - Started process 96 to run task
[2022-09-26T03:43:21.457+0000] {standard_task_runner.py:82} INFO - Running: ['***', 'tasks', 'run', 'tudo_melhor', 'colector', 'scheduled__2022-08-21T00:00:00+00:00', '--job-id', '65', '--raw', '--subdir', 'DAGS_FOLDER/dag.py', '--cfg-path', '/tmp/tmpqb1afw3v']
[2022-09-26T03:43:21.458+0000] {standard_task_runner.py:83} INFO - Job 65: Subtask colector
[2022-09-26T03:43:21.459+0000] {dagbag.py:525} INFO - Filling up the DagBag from /opt/***/dags/dag.py
[2022-09-26T03:43:22.368+0000] {task_command.py:384} INFO - Running <TaskInstance: tudo_melhor.colector scheduled__2022-08-21T00:00:00+00:00 [running]> on host f43703b1b479
[2022-09-26T03:43:22.430+0000] {taskinstance.py:1592} INFO - Exporting the following env vars:
AIRFLOW_CTX_DAG_OWNER=***
AIRFLOW_CTX_DAG_ID=tudo_melhor
AIRFLOW_CTX_TASK_ID=colector
AIRFLOW_CTX_EXECUTION_DATE=2022-08-21T00:00:00+00:00
AIRFLOW_CTX_TRY_NUMBER=2
AIRFLOW_CTX_DAG_RUN_ID=scheduled__2022-08-21T00:00:00+00:00
[2022-09-26T03:43:22.431+0000] {tasks.py:41} INFO - Defining DEC to export information
[2022-09-26T03:43:22.436+0000] {tasks.py:355} INFO - Reading prep dataframe
[2022-09-26T03:43:22.449+0000] {tasks.py:149} INFO - Instantiating the Browser with the requested settings
[2022-09-26T03:43:22.451+0000] {connectionpool.py:813} WARNING - Retrying (Retry(total=2, connect=None, read=None, redirect=None, status=None)) after connection broken by 'NewConnectionError('<urllib3.connection.HTTPConnection object at 0x7f4256982bd0>: Failed to establish a new connection: [Errno 111] Connection refused')': /wd/hub/session
[2022-09-26T03:43:22.452+0000] {connectionpool.py:813} WARNING - Retrying (Retry(total=1, connect=None, read=None, redirect=None, status=None)) after connection broken by 'NewConnectionError('<urllib3.connection.HTTPConnection object at 0x7f4256a70150>: Failed to establish a new connection: [Errno 111] Connection refused')': /wd/hub/session
[2022-09-26T03:43:22.453+0000] {connectionpool.py:813} WARNING - Retrying (Retry(total=0, connect=None, read=None, redirect=None, status=None)) after connection broken by 'NewConnectionError('<urllib3.connection.HTTPConnection object at 0x7f42569a1fd0>: Failed to establish a new connection: [Errno 111] Connection refused')': /wd/hub/session
[2022-09-26T03:43:22.453+0000] {taskinstance.py:1851} ERROR - Task failed with exception
Traceback (most recent call last):
  File "/home/airflow/.local/lib/python3.7/site-packages/urllib3/connection.py", line 175, in _new_conn
    (self._dns_host, self.port), self.timeout, **extra_kw
  File "/home/airflow/.local/lib/python3.7/site-packages/urllib3/util/connection.py", line 95, in create_connection
    raise err
  File "/home/airflow/.local/lib/python3.7/site-packages/urllib3/util/connection.py", line 85, in create_connection
    sock.connect(sa)
ConnectionRefusedError: [Errno 111] Connection refused

During handling of the above exception, another exception occurred:

Traceback (most recent call last):
  File "/home/airflow/.local/lib/python3.7/site-packages/urllib3/connectionpool.py", line 710, in urlopen
    chunked=chunked,
  File "/home/airflow/.local/lib/python3.7/site-packages/urllib3/connectionpool.py", line 398, in _make_request
    conn.request(method, url, **httplib_request_kw)
  File "/home/airflow/.local/lib/python3.7/site-packages/urllib3/connection.py", line 239, in request
    super(HTTPConnection, self).request(method, url, body=body, headers=headers)
  File "/usr/local/lib/python3.7/http/client.py", line 1281, in request
    self._send_request(method, url, body, headers, encode_chunked)
  File "/usr/local/lib/python3.7/http/client.py", line 1327, in _send_request
    self.endheaders(body, encode_chunked=encode_chunked)
  File "/usr/local/lib/python3.7/http/client.py", line 1276, in endheaders
    self._send_output(message_body, encode_chunked=encode_chunked)
  File "/usr/local/lib/python3.7/http/client.py", line 1036, in _send_output
    self.send(msg)
  File "/usr/local/lib/python3.7/http/client.py", line 976, in send
    self.connect()
  File "/home/airflow/.local/lib/python3.7/site-packages/urllib3/connection.py", line 205, in connect
    conn = self._new_conn()
  File "/home/airflow/.local/lib/python3.7/site-packages/urllib3/connection.py", line 187, in _new_conn
    self, "Failed to establish a new connection: %s" % e
urllib3.exceptions.NewConnectionError: <urllib3.connection.HTTPConnection object at 0x7f425699b1d0>: Failed to establish a new connection: [Errno 111] Connection refused

During handling of the above exception, another exception occurred:

Traceback (most recent call last):
  File "/home/airflow/.local/lib/python3.7/site-packages/airflow/operators/python.py", line 175, in execute
    return_value = self.execute_callable()
  File "/home/airflow/.local/lib/python3.7/site-packages/airflow/operators/python.py", line 193, in execute_callable
    return self.python_callable(*self.op_args, **self.op_kwargs)
  File "/opt/airflow/dags/tasks.py", line 357, in colector
    browser = config_browser(config)
  File "/opt/airflow/dags/tasks.py", line 161, in config_browser
    desired_capabilities=capabilities, options=options)
  File "/home/airflow/.local/lib/python3.7/site-packages/selenium/webdriver/remote/webdriver.py", line 270, in __init__
    self.start_session(capabilities, browser_profile)
  File "/home/airflow/.local/lib/python3.7/site-packages/selenium/webdriver/remote/webdriver.py", line 363, in start_session
    response = self.execute(Command.NEW_SESSION, parameters)
  File "/home/airflow/.local/lib/python3.7/site-packages/selenium/webdriver/remote/webdriver.py", line 426, in execute
    response = self.command_executor.execute(driver_command, params)
  File "/home/airflow/.local/lib/python3.7/site-packages/selenium/webdriver/remote/remote_connection.py", line 344, in execute
    return self._request(command_info[0], url, body=data)
  File "/home/airflow/.local/lib/python3.7/site-packages/selenium/webdriver/remote/remote_connection.py", line 366, in _request
    response = self._conn.request(method, url, body=body, headers=headers)
  File "/home/airflow/.local/lib/python3.7/site-packages/urllib3/request.py", line 79, in request
    method, url, fields=fields, headers=headers, **urlopen_kw
  File "/home/airflow/.local/lib/python3.7/site-packages/urllib3/request.py", line 170, in request_encode_body
    return self.urlopen(method, url, **extra_kw)
  File "/home/airflow/.local/lib/python3.7/site-packages/urllib3/poolmanager.py", line 376, in urlopen
    response = conn.urlopen(method, u.request_uri, **kw)
  File "/home/airflow/.local/lib/python3.7/site-packages/urllib3/connectionpool.py", line 828, in urlopen
    **response_kw
  File "/home/airflow/.local/lib/python3.7/site-packages/urllib3/connectionpool.py", line 828, in urlopen
    **response_kw
  File "/home/airflow/.local/lib/python3.7/site-packages/urllib3/connectionpool.py", line 828, in urlopen
    **response_kw
  File "/home/airflow/.local/lib/python3.7/site-packages/urllib3/connectionpool.py", line 788, in urlopen
    method, url, error=e, _pool=self, _stacktrace=sys.exc_info()[2]
  File "/home/airflow/.local/lib/python3.7/site-packages/urllib3/util/retry.py", line 592, in increment
    raise MaxRetryError(_pool, url, error or ResponseError(cause))
urllib3.exceptions.MaxRetryError: HTTPConnectionPool(host='localhost', port=4444): Max retries exceeded with url: /wd/hub/session (Caused by NewConnectionError('<urllib3.connection.HTTPConnection object at 0x7f425699b1d0>: Failed to establish a new connection: [Errno 111] Connection refused'))
[2022-09-26T03:43:22.464+0000] {taskinstance.py:1406} INFO - Marking task as FAILED. dag_id=tudo_melhor, task_id=colector, execution_date=20220821T000000, start_date=20220926T034321, end_date=20220926T034322
[2022-09-26T03:43:22.474+0000] {standard_task_runner.py:107} ERROR - Failed to execute job 65 for task colector (HTTPConnectionPool(host='localhost', port=4444): Max retries exceeded with url: /wd/hub/session (Caused by NewConnectionError('<urllib3.connection.HTTPConnection object at 0x7f425699b1d0>: Failed to establish a new connection: [Errno 111] Connection refused')); 96)
[2022-09-26T03:43:22.513+0000] {local_task_job.py:164} INFO - Task exited with return code 1
[2022-09-26T03:43:22.535+0000] {local_task_job.py:273} INFO - 0 downstream tasks scheduled from follow-on schedule check
