[2022-09-30T15:58:09.593+0000] {taskinstance.py:1165} INFO - Dependencies all met for <TaskInstance: encasa.colector manual__2022-09-26T01:58:51.913110+00:00 [queued]>
[2022-09-30T15:58:09.603+0000] {taskinstance.py:1165} INFO - Dependencies all met for <TaskInstance: encasa.colector manual__2022-09-26T01:58:51.913110+00:00 [queued]>
[2022-09-30T15:58:09.604+0000] {taskinstance.py:1362} INFO - 
--------------------------------------------------------------------------------
[2022-09-30T15:58:09.604+0000] {taskinstance.py:1363} INFO - Starting attempt 3 of 3
[2022-09-30T15:58:09.605+0000] {taskinstance.py:1364} INFO - 
--------------------------------------------------------------------------------
[2022-09-30T15:58:09.619+0000] {taskinstance.py:1383} INFO - Executing <Task(PythonOperator): colector> on 2022-09-26 01:58:51.913110+00:00
[2022-09-30T15:58:09.626+0000] {standard_task_runner.py:54} INFO - Started process 488 to run task
[2022-09-30T15:58:09.628+0000] {standard_task_runner.py:82} INFO - Running: ['***', 'tasks', 'run', 'encasa', 'colector', 'manual__2022-09-26T01:58:51.913110+00:00', '--job-id', '334', '--raw', '--subdir', 'DAGS_FOLDER/dag.py', '--cfg-path', '/tmp/tmpfu96f3k8']
[2022-09-30T15:58:09.628+0000] {standard_task_runner.py:83} INFO - Job 334: Subtask colector
[2022-09-30T15:58:09.629+0000] {dagbag.py:525} INFO - Filling up the DagBag from /opt/***/dags/dag.py
[2022-09-30T15:58:10.009+0000] {task_command.py:384} INFO - Running <TaskInstance: encasa.colector manual__2022-09-26T01:58:51.913110+00:00 [running]> on host dc20523c063c
[2022-09-30T15:58:10.066+0000] {taskinstance.py:1592} INFO - Exporting the following env vars:
AIRFLOW_CTX_DAG_OWNER=***
AIRFLOW_CTX_DAG_ID=encasa
AIRFLOW_CTX_TASK_ID=colector
AIRFLOW_CTX_EXECUTION_DATE=2022-09-26T01:58:51.913110+00:00
AIRFLOW_CTX_TRY_NUMBER=3
AIRFLOW_CTX_DAG_RUN_ID=manual__2022-09-26T01:58:51.913110+00:00
[2022-09-30T15:58:10.067+0000] {tasks.py:39} INFO - Defining DEC to export information
[2022-09-30T15:58:10.075+0000] {tasks.py:343} INFO - Reading prep dataframe
[2022-09-30T15:58:10.078+0000] {taskinstance.py:1851} ERROR - Task failed with exception
Traceback (most recent call last):
  File "/home/airflow/.local/lib/python3.7/site-packages/airflow/operators/python.py", line 175, in execute
    return_value = self.execute_callable()
  File "/home/airflow/.local/lib/python3.7/site-packages/airflow/operators/python.py", line 193, in execute_callable
    return self.python_callable(*self.op_args, **self.op_kwargs)
  File "/opt/airflow/dags/tasks.py", line 344, in colector
    dataframe = pd.read_csv(f"{path}/prep.csv", dtype=str)
  File "/home/airflow/.local/lib/python3.7/site-packages/pandas/util/_decorators.py", line 311, in wrapper
    return func(*args, **kwargs)
  File "/home/airflow/.local/lib/python3.7/site-packages/pandas/io/parsers/readers.py", line 586, in read_csv
    return _read(filepath_or_buffer, kwds)
  File "/home/airflow/.local/lib/python3.7/site-packages/pandas/io/parsers/readers.py", line 482, in _read
    parser = TextFileReader(filepath_or_buffer, **kwds)
  File "/home/airflow/.local/lib/python3.7/site-packages/pandas/io/parsers/readers.py", line 811, in __init__
    self._engine = self._make_engine(self.engine)
  File "/home/airflow/.local/lib/python3.7/site-packages/pandas/io/parsers/readers.py", line 1040, in _make_engine
    return mapping[engine](self.f, **self.options)  # type: ignore[call-arg]
  File "/home/airflow/.local/lib/python3.7/site-packages/pandas/io/parsers/c_parser_wrapper.py", line 51, in __init__
    self._open_handles(src, kwds)
  File "/home/airflow/.local/lib/python3.7/site-packages/pandas/io/parsers/base_parser.py", line 229, in _open_handles
    errors=kwds.get("encoding_errors", "strict"),
  File "/home/airflow/.local/lib/python3.7/site-packages/pandas/io/common.py", line 707, in get_handle
    newline="",
FileNotFoundError: [Errno 2] No such file or directory: './data_output/ENCASA/coleta_2022/coleta_setembro/coleta_3_dec/saida_2022_09_30/prep.csv'
[2022-09-30T15:58:10.091+0000] {taskinstance.py:1406} INFO - Marking task as FAILED. dag_id=encasa, task_id=colector, execution_date=20220926T015851, start_date=20220930T155809, end_date=20220930T155810
[2022-09-30T15:58:10.101+0000] {standard_task_runner.py:107} ERROR - Failed to execute job 334 for task colector ([Errno 2] No such file or directory: './data_output/ENCASA/coleta_2022/coleta_setembro/coleta_3_dec/saida_2022_09_30/prep.csv'; 488)
[2022-09-30T15:58:10.122+0000] {local_task_job.py:164} INFO - Task exited with return code 1
[2022-09-30T15:58:10.144+0000] {local_task_job.py:273} INFO - 0 downstream tasks scheduled from follow-on schedule check
