[2022-09-26T01:42:14.641+0000] {taskinstance.py:1165} INFO - Dependencies all met for <TaskInstance: encasa.colector scheduled__2022-09-25T00:00:00+00:00 [queued]>
[2022-09-26T01:42:14.652+0000] {taskinstance.py:1165} INFO - Dependencies all met for <TaskInstance: encasa.colector scheduled__2022-09-25T00:00:00+00:00 [queued]>
[2022-09-26T01:42:14.653+0000] {taskinstance.py:1362} INFO - 
--------------------------------------------------------------------------------
[2022-09-26T01:42:14.653+0000] {taskinstance.py:1363} INFO - Starting attempt 5 of 5
[2022-09-26T01:42:14.654+0000] {taskinstance.py:1364} INFO - 
--------------------------------------------------------------------------------
[2022-09-26T01:42:14.669+0000] {taskinstance.py:1383} INFO - Executing <Task(PythonOperator): colector> on 2022-09-25 00:00:00+00:00
[2022-09-26T01:42:14.673+0000] {standard_task_runner.py:54} INFO - Started process 2969 to run task
[2022-09-26T01:42:14.675+0000] {standard_task_runner.py:82} INFO - Running: ['***', 'tasks', 'run', 'encasa', 'colector', 'scheduled__2022-09-25T00:00:00+00:00', '--job-id', '22', '--raw', '--subdir', 'DAGS_FOLDER/dag.py', '--cfg-path', '/tmp/tmpzb5tiofk']
[2022-09-26T01:42:14.675+0000] {standard_task_runner.py:83} INFO - Job 22: Subtask colector
[2022-09-26T01:42:14.676+0000] {dagbag.py:525} INFO - Filling up the DagBag from /opt/***/dags/dag.py
[2022-09-26T01:42:15.091+0000] {task_command.py:384} INFO - Running <TaskInstance: encasa.colector scheduled__2022-09-25T00:00:00+00:00 [running]> on host 4df58d125c59
[2022-09-26T01:42:15.147+0000] {taskinstance.py:1592} INFO - Exporting the following env vars:
AIRFLOW_CTX_DAG_OWNER=***
AIRFLOW_CTX_DAG_ID=encasa
AIRFLOW_CTX_TASK_ID=colector
AIRFLOW_CTX_EXECUTION_DATE=2022-09-25T00:00:00+00:00
AIRFLOW_CTX_TRY_NUMBER=5
AIRFLOW_CTX_DAG_RUN_ID=scheduled__2022-09-25T00:00:00+00:00
[2022-09-26T01:42:15.148+0000] {taskinstance.py:1851} ERROR - Task failed with exception
Traceback (most recent call last):
  File "/home/airflow/.local/lib/python3.7/site-packages/airflow/operators/python.py", line 175, in execute
    return_value = self.execute_callable()
  File "/home/airflow/.local/lib/python3.7/site-packages/airflow/operators/python.py", line 193, in execute_callable
    return self.python_callable(*self.op_args, **self.op_kwargs)
  File "/opt/airflow/dags/tasks.py", line 344, in colector
    path = get_path(date=date)
  File "/opt/airflow/dags/tasks.py", line 71, in get_path
    locale.setlocale(locale.LC_ALL, "pt_BR")
  File "/usr/local/lib/python3.7/locale.py", line 608, in setlocale
    return _setlocale(category, locale)
locale.Error: unsupported locale setting
[2022-09-26T01:42:15.158+0000] {taskinstance.py:1406} INFO - Marking task as FAILED. dag_id=encasa, task_id=colector, execution_date=20220925T000000, start_date=20220926T014214, end_date=20220926T014215
[2022-09-26T01:42:15.167+0000] {standard_task_runner.py:107} ERROR - Failed to execute job 22 for task colector (unsupported locale setting; 2969)
[2022-09-26T01:42:15.208+0000] {local_task_job.py:164} INFO - Task exited with return code 1
[2022-09-26T01:42:15.231+0000] {local_task_job.py:273} INFO - 0 downstream tasks scheduled from follow-on schedule check
